Workbook

Sheet Summary
A1: Concordia University | D1: Group member names: | F1: Hugh Cronin
A2: John Molson School of Business | F2: Antonin Le Clei
A3: FINA 210 Project | F3: Abderrahmane Benchelabi
A4: Prof: Michel Deslauriers
A5: Fall 2021
A9: Summer 2021
A10: DEAL PARAMETERS | B10: Most likely | C10: Pessimistic | D10: Optimistic
A11: Asset type | B11: =+Likely!B4 -> Multi-Residential | C11: =+Pessimistic!B4 -> Multi-Residential | D11: =+Optimistic!B4 -> Multi-Residential
A12: Asking Price | B12: =+Likely!B5 -> 2685000 | C12: =+Pessimistic!B5 -> 2685000 | D12: =+Optimistic!B5 -> 2685000
A13: NOI - Year 1 | B13: =+Likely!B6 -> 118974.33 | C13: =+Pessimistic!B6 -> 116134.15 | D13: =+Optimistic!B6 -> 120940.42
A14: Implied Cap Rate | B14: =+Likely!B7 -> 0.044310739 | C14: =+Pessimistic!B7 -> 0.043252942 | D14: =+Optimistic!B7 -> 0.045042987
A15: Purchase Price | B15: =+Likely!B8 -> 2685000 | C15: =+Pessimistic!B8 -> 2695000 | D15: =+Optimistic!B8 -> 2675000
A16: Cap rate | B16: =+Likely!B9 -> 0.044310739 | C16: =+Pessimistic!B9 -> 0.043092448 | D16: =+Optimistic!B9 -> 0.045211372
A17: Financing amount | B17: =+Likely!B12 -> 1745250 | C17: =+Pessimistic!B12 -> 1617000 | D17: =+Optimistic!B12 -> 1872500
A18: Mortgage rate | B18: =+Likely!B13 -> 0.039 | C18: =+Pessimistic!B13 -> 0.042 | D18: =+Optimistic!B13 -> 0.035
A19: Mortgage amortization period | B19: =+Likely!B15 -> 25 | C19: =+Pessimistic!B15 -> 25 | D19: =+Optimistic!B15 -> 25
A20: Equity funding | B20: =+Likely!B16 -> 993450 | C20: =+Pessimistic!B16 -> 1131900 | D20: =+Optimistic!B16 -> 856000
A21: Exit cap rate | B21: =+Likely!B21 -> 0.044310739 | C21: =+Pessimistic!B21 -> 0.045 | D21: =+Optimistic!B21 -> 0.043
A22: Investor unlevered hurdle rate | B22: =+Likely!B23 -> 0.054310739 | C22: =+Pessimistic!B23 -> 0.06 | D22: =+Optimistic!B23 -> 0.063
A23: Investor levered hurdle rate | B23: =+Likely!B24 -> 0.0827 | C23: =+Pessimistic!B24 -> 0.0871 | D23: =+Optimistic!B24 -> 0.1284
A24: IRR AND NPV
A25: IRR unlevered | B25: =+Likely!B52 -> 0.071442256 | C25: =+Pessimistic!B52 -> 0.052791467 | D25: =+Optimistic!B52 -> 0.09076435
A26: NPV unlevered | B26: =+Likely!B53 -> 211475.05 | C26: =+Pessimistic!B53 -> -85013.866 | D26: =+Optimistic!B53 -> 345330.12
A27: IRR levered | B27: =+Likely!B65 -> 0.11726758 | C27: =+Pessimistic!B65 -> 0.067119595 | D27: =+Optimistic!B65 -> 0.17787468
A28: NPV levered | B28: =+Likely!B66 -> 165007.82 | C28: =+Pessimistic!B66 -> -97933.594 | D28: =+Optimistic!B66 -> 199776.09

Sheet Likely
A1: MOST LIKELY SCENARIO
A3: DEAL PARAMETERS | D3: PRI | F3: =+$B$34 -> 168096
A4: Asset type | B4: Multi-Residential | D4: Vacancy + Credit allowance | F4: =1.5%*F3 -> 2521.44
A5: Asking Price | B5: 2685000 | D5: ERI | F5: =F3-F4 -> 165574.56
A6: NOI - Year 1 | B6: =C36 -> 118974.33 | D6: Misc income | F6: 0
A7: Implied Cap rate | B7: =B6/B5 -> 0.044310739 | D7: GOI | F7: =F5 -> 165574.56
A8: Purchase Price | B8: 2685000 | D8: Operating expense | F8: =51142 -> 51142
A9: Cap rate | B9: =B6/B8 -> 0.044310739 | D9: NOI | F9: =F7-F8 -> 114432.56
A10: Acqusition expenses | B10: =0.02*B8 -> 53700
A11: Financing LTV | B11: 0.65
A12: Financing amount | B12: =B11*B8 -> 1745250
A13: Mortgage rate | B13: 0.039
A14: Mortgage monthly rate | B14: =NOMINAL(EFFECT(B13,2),12)/12 -> 0.0032239041 | E14: Weight | F14: Cost | G14: WACC
A15: Mortgage amortization period | B15: 25 | D15: Debt | E15: =B11 -> 0.65 | F15: =B13 -> 0.039
A16: Equity funding after leverage | B16: =B8-B12+B10 -> 993450 | D16: Equity | E16: =1-E15 -> 0.35 | F16: 0.0827
A17: Own Equity % | B17: 0.5 | F17: =(E15*F15)+(E16*F16) -> 0.054295 | G17: =B23 -> 0.054310739
A18: Investor Equity % | B18: 0.5
A19: Own Equity funding after leverage | B19: =B17*B16 -> 496725
A20: Investor Equity funding after leverage | B20: =B18*B16 -> 496725
A21: Exit cap rate | B21: =B7 -> 0.044310739
A22: Sale expenses | B22: 0.04 | C22: Of sale price
A23: Investor unlevered hurdle rate | B23: =B21+0.01 -> 0.054310739
A24: Investor levered hurdle rate | B24: =F16 -> 0.0827
A27: NOI AND CASH FLOW
B28: Actual | C28: Projected
B29: Last Year | C29: Year 1 | D29: Year 2 | E29: Year 3 | F29: Year 4 | G29: Year 5 | H29: Year 6
A31: Revenue growth percentage rate | C31: 0.035 | D31: 0.035 | E31: 0.035 | F31: 0.035 | G31: 0.035 | H31: 0.035
A32: Expense growth percentage rate | C32: 0.025 | D32: 0.025 | E32: 0.025 | F32: 0.025 | G32: 0.025 | H32: 0.025
A34: Revenues | B34: 168096 | C34: =+B34*(1+C31) -> 173979.36 | D34: =+C34*(1+D31) -> 180068.64 | E34: =+D34*(1+E31) -> 186371.04 | F34: =+E34*(1+F31) -> 192894.03 | G34: =+F34*(1+G31) -> 199645.32 | H34: =+G34*(1+H31) -> 206632.9
A35: Expenses | B35: =F8+F4 -> 53663.44 | C35: =+B35*(1+C32) -> 55005.026 | D35: =+C35*(1+D32) -> 56380.152 | E35: =+D35*(1+E32) -> 57789.655 | F35: =+E35*(1+F32) -> 59234.397 | G35: =+F35*(1+G32) -> 60715.257 | H35: =+G35*(1+H32) -> 62233.138
A36: NOI | B36: =B34-B35 -> 114432.56 | C36: =C34-C35 -> 118974.33 | D36: =+D34-D35 -> 123688.49 | E36: =+E34-E35 -> 128581.38 | F36: =+F34-F35 -> 133659.63 | G36: =+G34-G35 -> 138930.06 | H36: =+H34-H35 -> 144399.77
A37: Other cash flow items (if required) | B37: 0 | D37: 0 | E37: 0 | F37: 0 | G37: 0 | H37: 0
A38: Debts servicing | C38: =$C$72*12 -> -109032.04 | D38: =$C$72*12 -> -109032.04 | E38: =$C$72*12 -> -109032.04 | F38: =$C$72*12 -> -109032.04 | G38: =$C$72*12 -> -109032.04
A39: Cash flow | B39: =B36-B37+B38 -> 114432.56 | C39: =+C36-C37+C38 -> 9942.297 | D39: =+D36-D37+D38 -> 14656.449 | E39: =+E36-E37+E38 -> 19549.347 | F39: =+F36-F37+F38 -> 24627.592 | G39: =+G36-G37+G38 -> 29898.023 | H39: =+H36-H37+H38 -> 144399.77
A44: UNLEVERED CASH FLOWS
B45: Initial | C45: Year 1 | D45: Year 2 | E45: Year 3 | F45: Year 4 | G45: Year 5
A46: Investment | B46: =-B8-B10 -> -2738700
A47: Cash flow | C47: =C36-C37 -> 118974.33 | D47: =D39-D38 -> 123688.49 | E47: =E39-E38 -> 128581.38 | F47: =F39-F38 -> 133659.63 | G47: =G39-G38 -> 138930.06
A48: Cash on exit | G48: =(H36/$B$21)*(1-B22) -> 3128446.5
B49: =SUM(B46:B48) -> -2738700 | C49: =SUM(C46:C48) -> 118974.33 | D49: =SUM(D46:D48) -> 123688.49 | E49: =SUM(E46:E48) -> 128581.38 | F49: =SUM(F46:F48) -> 133659.63 | G49: =SUM(G46:G48) -> 3267376.5
...

Sheet Pessimistic
A1: PESSIMISTIC SCENARIO
A3: DEAL PARAMETERS | D3: PRI | F3: =+$B$34 -> 168096
A4: Asset type | B4: Multi-Residential | D4: Vacancy + Credit allowance | F4: =2.5%*F3 -> 4202.4
A5: Asking Price | B5: 2685000 | D5: ERI | F5: =F3-F4 -> 163893.6
A6: NOI - Year 1 | B6: =+C36 -> 116134.15 | D6: Misc income | F6: 0
A7: Implied Cap rate | B7: =B6/B5 -> 0.043252942 | D7: GOI | F7: =F5 -> 163893.6
A8: Purchase Price | B8: 2695000 | D8: Operating expense | F8: =51142 -> 51142
A9: Cap rate | B9: =B6/B8 -> 0.043092448 | D9: NOI | F9: =F7-F8 -> 112751.6
A10: Acqusition expenses | B10: =0.02*B8 -> 53900
A11: Financing LTV | B11: 0.6
A12: Financing amount | B12: =B11*B8 -> 1617000
A13: Mortgage rate | B13: 0.042
A14: Mortgage monthly rate | B14: =NOMINAL(EFFECT(B13,2),12)/12 -> 0.0034697623
A15: Mortgage amortization period | B15: 25 | E15: Weight | F15: Cost | G15: WACC
A16: Equity funding after leverage | B16: =B8-B12+B10 -> 1131900 | D16: Debt | E16: =B11 -> 0.6 | F16: =B13 -> 0.042
A17: Own Equity % | B17: 0.5 | D17: Equity | E17: =1-E16 -> 0.4 | F17: 0.0871
A18: Investor Equity % | B18: 0.5 | F18: =(E16*F16)+(E17*F17) -> 0.06004 | G18: 0.06
A19: Own Equity funding after leverage | B19: =B17*B16 -> 565950
A20: Investor Equity funding after leverage | B20: =B18*B16 -> 565950
A21: Exit cap rate | B21: 0.045
A22: Sale expenses | B22: 0.04 | C22: Of sale price
A23: Investor unlevered hurdle rate | B23: =B21+0.015 -> 0.06
A24: Investor levered hurdle rate | B24: =F17 -> 0.0871
A27: NOI AND CASH FLOW
B28: Actual | C28: Projected
B29: Last Year | C29: Year 1 | D29: Year 2 | E29: Year 3 | F29: Year 4 | G29: Year 5 | H29: Year 6
A31: Revenue growth percentage rate | C31: 0.03 | D31: 0.03 | E31: 0.03 | F31: 0.03 | G31: 0.03 | H31: 0.03
A32: Expense growth percentage rate | C32: 0.03 | D32: 0.03 | E32: 0.03 | F32: 0.03 | G32: 0.03 | H32: 0.03
A34: Revenues | B34: 168096 | C34: =B34*(1+C31) -> 173138.88 | D34: =C34*(1+D31) -> 178333.05 | E34: =D34*(1+E31) -> 183683.04 | F34: =E34*(1+F31) -> 189193.53 | G34: =F34*(1+G31) -> 194869.33 | H34: =G34*(1+H31) -> 200715.41
A35: Expenses | B35: =F4+F8 -> 55344.4 | C35: =B35*(1+C32) -> 57004.732 | D35: =C35*(1+D32) -> 58714.874 | E35: =D35*(1+E32) -> 60476.32 | F35: =E35*(1+F32) -> 62290.61 | G35: =F35*(1+G32) -> 64159.328 | H35: =G35*(1+H32) -> 66084.108
A36: NOI | B36: =B34-B35 -> 112751.6 | C36: =+C34-C35 -> 116134.15 | D36: =+D34-D35 -> 119618.17 | E36: =+E34-E35 -> 123206.72 | F36: =+F34-F35 -> 126902.92 | G36: =+G34-G35 -> 130710.01 | H36: =+H34-H35 -> 134631.31
A37: Other cash flow items (if required)
A38: Debts servicing | C38: =$C$72*12 -> -104183.62 | D38: =$C$72*12 -> -104183.62 | E38: =$C$72*12 -> -104183.62 | F38: =$C$72*12 -> -104183.62 | G38: =$C$72*12 -> -104183.62 | H38: =$C$72*12 -> -104183.62
A39: Cash flow | B39: =+B36-B37+B38 -> 112751.6 | C39: =+C36-C37+C38 -> 11950.531 | D39: =+D36-D37+D38 -> 15434.555 | E39: =+E36-E37+E38 -> 19023.1 | F39: =+F36-F37+F38 -> 22719.302 | G39: =+G36-G37+G38 -> 26526.389 | H39: =+H36-H37+H38 -> 30447.689
A44: UNLEVERED CASH FLOWS
B45: Initial | C45: Year 1 | D45: Year 2 | E45: Year 3 | F45: Year 4 | G45: Year 5
A46: Investment | B46: =-B8-B10 -> -2748900
A47: Cash flow | C47: =C39-C38 -> 116134.15 | D47: =D39-D38 -> 119618.17 | E47: =E39-E38 -> 123206.72 | F47: =F39-F38 -> 126902.92 | G47: =G39-G38 -> 130710.01
A48: Cash on exit | G48: =(H36/$B$21)*(1-B22) -> 2872134.5
B49: =SUM(B46:B48) -> -2748900 | C49: =SUM(C46:C48) -> 116134.15 | D49: =SUM(D46:D48) -> 119618.17 | E49: =SUM(E46:E48) -> 123206.72 | F49: =SUM(F46:F48) -> 126902.92 | G49: =SUM(G46:G48) -> 3002844.6
...

Sheet Optimistic
A1: OPTIMISTIC SCENARIO
A3: DEAL PARAMETERS | D3: PRI | F3: =+$B$34 -> 168096
A4: Asset type | B4: Multi-Residential | D4: Vacancy + Credit allowance | F4: =1%*F3 -> 1680.96
A5: Asking Price | B5: 2685000 | D5: ERI | F5: =F3-F4 -> 166415.04
A6: NOI - Year 1 | B6: =+C36 -> 120940.42 | D6: Misc income | F6: 0
A7: Implied Cap rate | B7: =B6/B5 -> 0.045042987 | D7: GOI | F7: =F5 -> 166415.04
A8: Purchase Price | B8: 2675000 | D8: Operating expense | F8: =51142 -> 51142
A9: Cap rate | B9: =B6/B8 -> 0.045211372 | D9: NOI | F9: =F7-F8 -> 115273.04
A10: Acqusition expenses | B10: =0.02*B8 -> 53500
A11: Financing LTV | B11: 0.7
A12: Financing amount | B12: =B11*B8 -> 1872500
A13: Mortgage rate | B13: 0.035 | E13: Weight | F13: Cost | G13: WACC
A14: Mortgage monthly rate | B14: =NOMINAL(EFFECT(B13,2),12)/12 -> 0.002895624 | D14: Debt | E14: =B11 -> 0.7 | F14: =B13 -> 0.035
A15: Mortgage amortization period | B15: 25 | D15: Equity | E15: =1-E14 -> 0.3 | F15: 0.1284
A16: Equity funding after leverage | B16: =B8-B12+B10 -> 856000 | F16: =(E14*F14)+(E15*F15) -> 0.06302 | G16: =B21+0.02 -> 0.063
A17: Own Equity % | B17: 0.5
A18: Investor Equity % | B18: 0.5
A19: Own Equity funding after leverage | B19: =B17*B16 -> 428000
A20: Investor Equity funding after leverage | B20: =B18*B16 -> 428000
A21: Exit cap rate | B21: 0.043
A22: Sale expenses | B22: 0.04 | C22: Of sale price
A23: Investor unlevered hurdle rate | B23: =6.3% -> 0.063
A24: Investor levered hurdle rate | B24: =F15 -> 0.1284
A27: NOI AND CASH FLOW
B28: Actual | C28: Projected
B29: Last Year | C29: Year 1 | D29: Year 2 | E29: Year 3 | F29: Year 4 | G29: Year 5 | H29: Year 6
A31: Revenue growth percentage rate | C31: 0.04 | D31: 0.04 | E31: 0.04 | F31: 0.04 | G31: 0.04 | H31: 0.04
A32: Expense growth percentage rate | C32: 0.02 | D32: 0.02 | E32: 0.02 | F32: 0.02 | G32: 0.02 | H32: 0.02
A34: Revenues | B34: 168096 | C34: =B34*(1+C31) -> 174819.84 | D34: =C34*(1+D31) -> 181812.63 | E34: =D34*(1+E31) -> 189085.14 | F34: =E34*(1+F31) -> 196648.54 | G34: =F34*(1+G31) -> 204514.49 | H34: =G34*(1+H31) -> 212695.07
A35: Expenses | B35: =F4+F8 -> 52822.96 | C35: =B35*(1+C32) -> 53879.419 | D35: =C35*(1+D32) -> 54957.008 | E35: =D35*(1+E32) -> 56056.148 | F35: =E35*(1+F32) -> 57177.271 | G35: =F35*(1+G32) -> 58320.816 | H35: =G35*(1+H32) -> 59487.232
A36: NOI | B36: =B34-B35 -> 115273.04 | C36: =+C34-C35 -> 120940.42 | D36: =+D34-D35 -> 126855.63 | E36: =+E34-E35 -> 133028.99 | F36: =+F34-F35 -> 139471.27 | G36: =+G34-G35 -> 146193.67 | H36: =+H34-H35 -> 153207.83
A37: Other cash flow items (if required)
A38: Debts servicing | C38: =$C$72*12 -> -112186.04 | D38: =$C$72*12 -> -112186.04 | E38: =$C$72*12 -> -112186.04 | F38: =$C$72*12 -> -112186.04 | G38: =$C$72*12 -> -112186.04
A39: Cash flow | B39: =B36 -> 115273.04 | C39: =+C36-C37+C38 -> 8754.3771 | D39: =+D36-D37+D38 -> 14669.582 | E39: =+E36-E37+E38 -> 20842.948 | F39: =+F36-F37+F38 -> 27285.23 | G39: =+G36-G37+G38 -> 34007.626 | H39: =+H36-H37+H38 -> 153207.83
A44: UNLEVERED CASH FLOWS
B45: Initial | C45: Year 1 | D45: Year 2 | E45: Year 3 | F45: Year 4 | G45: Year 5
A46: Investment | B46: =-B8-B10 -> -2728500
A47: Cash flow | C47: =C39-C38 -> 120940.42 | D47: =D39-D38 -> 126855.63 | E47: =E39-E38 -> 133028.99 | F47: =F39-F38 -> 139471.27 | G47: =G39-G38 -> 146193.67
A48: Cash on exit | G48: =(H36/$B$21)*(1-B22) -> 3420454
B49: =SUM(B46:B48) -> -2728500 | C49: =SUM(C46:C48) -> 120940.42 | D49: =SUM(D46:D48) -> 126855.63 | E49: =SUM(E46:E48) -> 133028.99 | F49: =SUM(F46:F48) -> 139471.27 | G49: =SUM(G46:G48) -> 3566647.6
...
